Workbook

Sheet Spirits Menu
A1: Spirits
A2: Every spirit on the back bar, grouped by type. Yellow price cells are waiting for SpotOn prices.
A4: Spirit | B4: Price
A6: VODKA
A7: Belvedere Organic
A8: Grey Goose
A9: Ketel One
A10: Tito's
A12: GIN
A13: Bombay Sapphire
A14: The Botanist
A15: Empress 1908 Cucumber Lemon
A16: Hendrick's
A17: Roku
A18: Sipsmith London Dry
... A151: St. George Bruto Americano

Sheet Inventory
A1: Back-Bar Bottle Inventory
A2: ="Built from 4 shelf photos: "&SUM(G5:G116)&" bottles across "&COUNTA(D5:D116)&" products. Each bottle is counted once, even where photos overlap." -> Built from 4 shelf photos: 114 bottles across 112 products. Each bottle is counted once, even where photos overlap.
A4: # | B4: Category | C4: Style | D4: Brand | E4: Expression | F4: Origin | G4: Qty | H4: Where in the photos | I4: ID confidence | J4: Notes
A5: 1 | B5: Vodka | C5: Vodka | D5: Belvedere | E5: Organic | F5: Poland | G5: 1 | H5: Photo 4 · bottom shelf | I5: Medium | J5: Frosted bottle with a white tree; label partly hidden (reads '…EDERE ORGANIC VODKA').
A6: 2 | B6: Vodka | C6: Vodka | D6: Grey Goose | E6: Vodka | F6: France | G6: 1 | H6: Photo 4 · bottom shelf | I6: High
A7: 3 | B7: Vodka | C7: Vodka | D7: Ketel One | E7: Vodka | F7: Netherlands | G7: 1 | H7: Photo 4 · bottom shelf | I7: High
A8: 4 | B8: Vodka | C8: Vodka | D8: Tito's | E8: Handmade Vodka | F8: USA | G8: 1 | H8: Photo 4 · bottom shelf | I8: Low | J8: Label faces sideways; only '…'s' and '…de' are visible. Worth checking.
A9: 5 | B9: Gin | C9: London dry | D9: Bombay Sapphire | E9: London Dry Gin | F9: England | G9: 1 | H9: Photo 1 · bottom shelf, back left | I9: Medium | J9: Partly hidden; blue bottle with 'BOMBAY' label.
A10: 6 | B10: Gin | C10: Dry gin | D10: The Botanist | E10: Islay Dry Gin 22 | F10: Scotland | G10: 1 | H10: Photo 4 · bottom shelf | I10: High
A11: 7 | B11: Gin | C11: Flavored gin | D11: Empress 1908 | E11: Cucumber Lemon Gin | F11: Canada | G11: 1 | H11: Photo 4 · bottom shelf | I11: High
A12: 8 | B12: Gin | C12: Distilled gin | D12: Hendrick's | E12: Gin | F12: Scotland | G12: 1 | H12: Photo 4 · bottom shelf (also Photo 1) | I12: High
A13: 9 | B13: Gin | C13: Japanese gin | D13: Roku | E13: Japanese Craft Gin | F13: Japan | G13: 1 | H13: Photo 4 · bottom shelf | I13: High | J13: Made by Suntory.
A14: 10 | B14: Gin | C14: London dry | D14: Sipsmith | E14: London Dry Gin | F14: England | G14: 1 | H14: Photo 4 · bottom shelf | I14: High
A15: 11 | B15: Gin | C15: London dry | D15: Tanqueray | E15: London Dry Gin | F15: Scotland | G15: 1 | H15: Photo 4 · bottom shelf | I15: High
A16: 12 | B16: Rum | C16: Black rum | D16: Gosling's | E16: Black Seal | F16: Bermuda | G16: 1 | H16: Photo 2 · bottom shelf, left bay | I16: High
A17: 13 | B17: Tequila | C17: Blanco | D17: Casamigos | E17: Blanco | F17: Mexico | G17: 1 | H17: Photo 2 · bottom shelf | I17: High
A18: 14 | B18: Tequila | C18: Blanco | D18: Clase Azul | E18: Plata | F18: Mexico | G18: 1 | H18: Photo 3 · top shelf | I18: Medium | J18: Clear glass decanter with a flower emblem; named from the decanter design (no label text visible).
A19: 15 | B19: Tequila | C19: Blanco | D19: Don Fulano | E19: Blanco | F19: Mexico | G19: 1 | H19: Photo 2 · middle shelf | I19: High
A20: 16 | B20: Tequila | C20: Blanco | D20: Don Julio | E20: Blanco | F20: Mexico | G20: 1 | H20: Photo 2 · bottom shelf | I20: High
A21: 17 | B21: Tequila | C21: Blanco | D21: Dulce Vida | E21: Organic Blanco (100 proof) | F21: Mexico | G21: 1 | H21: Photo 2 · top shelf | I21: High
A22: 18 | B22: Tequila | C22: Blanco | D22: El Tequileño | E22: Platinum | F22: Mexico | G22: 1 | H22: Photo 2 · bottom shelf | I22: High
A23: 19 | B23: Tequila | C23: Blanco | D23: El Tesoro | E23: Blanco | F23: Mexico | G23: 1 | H23: Photo 2 · bottom shelf | I23: High
A24: 20 | B24: Tequila | C24: Blanco | D24: Espolòn | E24: Blanco | F24: Mexico | G24: 1 | H24: Photo 2 · bottom shelf, left bay | I24: Medium | J24: Expression judged from the label design.
A25: 21 | B25: Tequila | C25: Blanco | D25: Fortaleza | E25: Blanco | F25: Mexico | G25: 1 | H25: Photo 2 · middle shelf | I25: High
A26: 22 | B26: Tequila | C26: Blanco | D26: Fortaleza | E26: Blanco Still Strength | F26: Mexico | G26: 1 | H26: Photo 2 · middle shelf | I26: High
A27: 23 | B27: Tequila | C27: Blanco | D27: Gran Patrón | E27: Platinum | F27: Mexico | G27: 1 | H27: Photo 2 · top shelf | I27: Low | J27: Tall crystal decanter etched 'PATRÓN'; expression not readable, Platinum is a best guess.
A28: 24 | B28: Tequila | C28: Blanco | D28: Irlandés | E28: Blanco | F28: Mexico | G28: 1 | H28: Photo 2 · bottom shelf | I28: High | J28: Shamrock label.
A29: 25 | B29: Tequila | C29: Blanco | D29: Lunazul | E29: Blanco | F29: Mexico | G29: 1 | H29: Photo 2 · bottom shelf | I29: High
A30: 26 | B30: Tequila | C30: Blanco | D30: Mijenta | E30: Blanco | F30: Mexico | G30: 1 | H30: Photo 2 · middle shelf | I30: High
A31: 27 | B31: Tequila | C31: Blanco | D31: Patrón | E31: Silver | F31: Mexico | G31: 1 | H31: Photo 2 · bottom shelf | I31: High
A32: 28 | B32: Tequila | C32: Blanco | D32: Siete Leguas | E32: Blanco | F32: Mexico | G32: 1 | H32: Photo 2 · bottom shelf | I32: High
A33: 29 | B33: Tequila | C33: Blanco | D33: Tequila Ocho | E33: Plata | F33: Mexico | G33: 1 | H33: Photo 2 · middle shelf | I33: High
A34: 30 | B34: Tequila | C34: Joven | D34: Clase Azul | E34: Gold | F34: Mexico | G34: 1 | H34: Photo 3 · top shelf (also Photo 1) | I34: Medium | J34: Glass decanter on a black ceramic base; named from the decanter design (no label text visible).
A35: 31 | B35: Tequila | C35: Reposado | D35: Casamigos | E35: Reposado | F35: Mexico | G35: 1 | H35: Photo 2 · bottom shelf | I35: High
A36: 32 | B36: Tequila | C36: Reposado | D36: Clase Azul | E36: Reposado | F36: Mexico | G36: 1 | H36: Photo 3 · top shelf (also Photo 1) | I36: High | J36: White ceramic decanter with cobalt-blue painting.
A37: 33 | B37: Tequila | C37: Reposado | D37: Don Julio | E37: Reposado | F37: Mexico | G37: 1 | H37: Photo 2 · bottom shelf | I37: High
A38: 34 | B38: Tequila | C38: Reposado | D38: Dulce Vida | E38: Organic Reposado | F38: Mexico | G38: 1 | H38: Photo 2 · top shelf | I38: High
A39: 35 | B39: Tequila | C39: Reposado | D39: El Tequileño | E39: Reposado | F39: Mexico | G39: 1 | H39: Photo 2 · bottom shelf | I39: High
A40: 36 | B40: Tequila | C40: Reposado | D40: El Tesoro | E40: Reposado | F40: Mexico | G40: 1 | H40: Photo 2 · bottom shelf | I40: High
A41: 37 | B41: Tequila | C41: Reposado | D41: Irlandés | E41: Reposado | F41: Mexico | G41: 1 | H41: Photo 2 · bottom shelf | I41: High | J41: Shamrock label.
...

Sheet Summary
A1: Summary
A3: By category
A4: Category | B4: Products | C4: Bottles
A5: Vodka | B5: =COUNTIF(Inventory!$B$5:$B$116,A5) -> 4 | C5: =SUMIF(Inventory!$B$5:$B$116,A5,Inventory!$G$5:$G$116) -> 4
A6: Gin | B6: =COUNTIF(Inventory!$B$5:$B$116,A6) -> 7 | C6: =SUMIF(Inventory!$B$5:$B$116,A6,Inventory!$G$5:$G$116) -> 7
A7: Rum | B7: =COUNTIF(Inventory!$B$5:$B$116,A7) -> 1 | C7: =SUMIF(Inventory!$B$5:$B$116,A7,Inventory!$G$5:$G$116) -> 1
A8: Tequila | B8: =COUNTIF(Inventory!$B$5:$B$116,A8) -> 43 | C8: =SUMIF(Inventory!$B$5:$B$116,A8,Inventory!$G$5:$G$116) -> 43
A9: Mezcal | B9: =COUNTIF(Inventory!$B$5:$B$116,A9) -> 9 | C9: =SUMIF(Inventory!$B$5:$B$116,A9,Inventory!$G$5:$G$116) -> 9
A10: Bourbon | B10: =COUNTIF(Inventory!$B$5:$B$116,A10) -> 18 | C10: =SUMIF(Inventory!$B$5:$B$116,A10,Inventory!$G$5:$G$116) -> 19
A11: Rye Whiskey | B11: =COUNTIF(Inventory!$B$5:$B$116,A11) -> 4 | C11: =SUMIF(Inventory!$B$5:$B$116,A11,Inventory!$G$5:$G$116) -> 4
A12: American Whiskey | B12: =COUNTIF(Inventory!$B$5:$B$116,A12) -> 2 | C12: =SUMIF(Inventory!$B$5:$B$116,A12,Inventory!$G$5:$G$116) -> 2
A13: Irish Whiskey | B13: =COUNTIF(Inventory!$B$5:$B$116,A13) -> 2 | C13: =SUMIF(Inventory!$B$5:$B$116,A13,Inventory!$G$5:$G$116) -> 2
A14: Scotch Whisky | B14: =COUNTIF(Inventory!$B$5:$B$116,A14) -> 13 | C14: =SUMIF(Inventory!$B$5:$B$116,A14,Inventory!$G$5:$G$116) -> 13
A15: Japanese Whisky | B15: =COUNTIF(Inventory!$B$5:$B$116,A15) -> 6 | C15: =SUMIF(Inventory!$B$5:$B$116,A15,Inventory!$G$5:$G$116) -> 7
A16: Amaro & Liqueur | B16: =COUNTIF(Inventory!$B$5:$B$116,A16) -> 3 | C16: =SUMIF(Inventory!$B$5:$B$116,A16,Inventory!$G$5:$G$116) -> 3
A17: Identified total | B17: =SUM(B5:B16) -> 112 | C17: =SUM(C5:C16) -> 114
A18: Not identified (see Unidentified tab) | C18: =SUM(Unidentified!$D$5:$D$14) -> 10
A19: Bottles counted | C19: =C17+C18 -> 124
A21: Tequila by style
A22: Style | B22: Products | C22: Bottles
A23: Blanco | B23: =COUNTIFS(Inventory!$B$5:$B$116,"Tequila",Inventory!$C$5:$C$116,A23) -> 17 | C23: =SUMIFS(Inventory!$G$5:$G$116,Inventory!$B$5:$B$116,"Tequila",Inventory!$C$5:$C$116,A23) -> 17
A24: Joven | B24: =COUNTIFS(Inventory!$B$5:$B$116,"Tequila",Inventory!$C$5:$C$116,A24) -> 1 | C24: =SUMIFS(Inventory!$G$5:$G$116,Inventory!$B$5:$B$116,"Tequila",Inventory!$C$5:$C$116,A24) -> 1
A25: Reposado | B25: =COUNTIFS(Inventory!$B$5:$B$116,"Tequila",Inventory!$C$5:$C$116,A25) -> 11 | C25: =SUMIFS(Inventory!$G$5:$G$116,Inventory!$B$5:$B$116,"Tequila",Inventory!$C$5:$C$116,A25) -> 11
A26: Añejo | B26: =COUNTIFS(Inventory!$B$5:$B$116,"Tequila",Inventory!$C$5:$C$116,A26) -> 8 | C26: =SUMIFS(Inventory!$G$5:$G$116,Inventory!$B$5:$B$116,"Tequila",Inventory!$C$5:$C$116,A26) -> 8
A27: Extra añejo | B27: =COUNTIFS(Inventory!$B$5:$B$116,"Tequila",Inventory!$C$5:$C$116,A27) -> 3 | C27: =SUMIFS(Inventory!$G$5:$G$116,Inventory!$B$5:$B$116,"Tequila",Inventory!$C$5:$C$116,A27) -> 3
A28: Aged blend | B28: =COUNTIFS(Inventory!$B$5:$B$116,"Tequila",Inventory!$C$5:$C$116,A28) -> 1 | C28: =SUMIFS(Inventory!$G$5:$G$116,Inventory!$B$5:$B$116,"Tequila",Inventory!$C$5:$C$116,A28) -> 1
A29: Unconfirmed | B29: =COUNTIFS(Inventory!$B$5:$B$116,"Tequila",Inventory!$C$5:$C$116,A29) -> 2 | C29: =SUMIFS(Inventory!$G$5:$G$116,Inventory!$B$5:$B$116,"Tequila",Inventory!$C$5:$C$116,A29) -> 2
A31: How sure each ID is
A32: ID confidence | B32: Products | C32: Bottles
A33: High | B33: =COUNTIF(Inventory!$I$5:$I$116,A33) -> 95 | C33: =SUMIF(Inventory!$I$5:$I$116,A33,Inventory!$G$5:$G$116) -> 96
A34: Medium | B34: =COUNTIF(Inventory!$I$5:$I$116,A34) -> 14 | C34: =SUMIF(Inventory!$I$5:$I$116,A34,Inventory!$G$5:$G$116) -> 15
A35: Low | B35: =COUNTIF(Inventory!$I$5:$I$116,A35) -> 3 | C35: =SUMIF(Inventory!$I$5:$I$116,A35,Inventory!$G$5:$G$116) -> 3
A37: How this was counted
A38: Photo 1: Center bays: Japanese whisky, bourbon and rye (Hatozaki, Weller, Basil Hayden, Angel's Envy).
A39: Photo 2: Tequila wall (Tequila Ocho, Fortaleza, El Tesoro, Don Julio, Patrón).
A40: Photo 3: Upper shelves: Clase Azul decanters and mezcal.
A41: Photo 4: Left wall by the warning sign: Scotch, gin and vodka.
A42: Overlaps: The photos overlap. A bottle seen in two photos is counted once and marked 'also Photo X'.
A43: Mirrors: The shelves are backed by mirrors. Reflected (backwards) labels are not counted.
A44: Qty: Bottles visible in the photos, not fill levels. Bottles hidden behind others can't be counted.
...

Sheet Unidentified
A1: Bottles seen but not identified
A2: Visible in the photos, but the label was hidden, turned away or cut off. Fill in the brand once you check the shelf.
A4: # | B4: Where in the photos | C4: What's visible | D4: Qty | E4: Brand / product (fill in)
A5: 1 | B5: Photo 4 · bottom shelf (also Photo 1) | C5: Gin in a black, bumpy (hobnail) bottle. Label reads '…STILL… GIN'; brand not visible. | D5: 1
A6: 2 | B6: Photo 1 · bottom shelf, back row | C6: Two frosted-glass bottles with black caps, behind Rabbit Hole. Labels not visible. | D6: 2
A7: 3 | B7: Photo 1 · bottom shelf | C7: Clear round bottle with a black cap and an embossed seal, between Maker's Mark and Four Roses. Label turned away. | D7: 1
A8: 4 | B8: Photo 1 · bottom shelf, back row | C8: Small bottle with silver shimmer in the liquid, behind Four Roses Single Barrel. | D8: 1
A9: 5 | B9: Photo 1 · bottom shelf, back row | C9: Bottle with dark liquid, behind Eagle Rare. | D9: 1
A10: 6 | B10: Photo 2 · bottom shelf, left bay | C10: Bottle in the back row with a black neck label starting 'CHA…'. | D10: 1
A11: 7 | B11: Photo 2 · bottom shelf, left bay | C11: Tall bottle with a blue cap and a coconut-and-lime label, behind Gosling's. | D11: 1
A12: 8 | B12: Photo 2 · bottom shelf, left bay | C12: Bottle with a black oval logo, partly hidden behind Gosling's. | D12: 1
A13: 9 | B13: Photo 2 · bottom shelf, left bay | C13: Green bottle behind Fernet-Branca; only the neck shows. | D13: 1
A14: 10 | B14: Photo 3 · bottom edge of photo | C14: Lower rail cut off by the photo, only bottle necks visible (about 20). Neck labels include 'Louisville Kentucky', '…Watermelon' and '…Melon'.
